Internal Server Error: /user/
Traceback (most recent call last):
  File "C:\Users\97797\AppData\Local\Programs\Python\Python311\Lib\site-packages\django\core\handlers\exception.py", line 55, in inner
    response = get_response(request)
               ^^^^^^^^^^^^^^^^^^^^^
  File "C:\Users\97797\AppData\Local\Programs\Python\Python311\Lib\site-packages\django\core\handlers\base.py", line 197, in _get_response
    response = wrapped_callback(request, *callback_args, **callback_kwargs)
               ^^^^^^^^^^^^^^^^^^^^^^^^^^^^^^^^^^^^^^^^^^^^^^^^^^^^^^^^^^^^
  File "C:\Users\97797\AppData\Local\Programs\Python\Python311\Lib\site-packages\django\views\generic\base.py", line 104, in view
    return self.dispatch(request, *args, **kwargs)
           ^^^^^^^^^^^^^^^^^^^^^^^^^^^^^^^^^^^^^^^
  File "C:\Users\97797\AppData\Local\Programs\Python\Python311\Lib\site-packages\django\contrib\auth\mixins.py", line 73, in dispatch
    return super().dispatch(request, *args, **kwargs)
           ^^^^^^^^^^^^^^^^^^^^^^^^^^^^^^^^^^^^^^^^^^
  File "C:\Users\97797\AppData\Local\Programs\Python\Python311\Lib\site-packages\django\views\generic\base.py", line 143, in dispatch
    return handler(request, *args, **kwargs)
           ^^^^^^^^^^^^^^^^^^^^^^^^^^^^^^^^^
  File "C:\Users\97797\OneDrive\Desktop\Donation Manager Github\DonationManagementSystem\UserManagement\views.py", line 75, in post
    user = get_object_or_404(CustomUser,request.user)
           ^^^^^^^^^^^^^^^^^^^^^^^^^^^^^^^^^^^^^^^^^^
  File "C:\Users\97797\AppData\Local\Programs\Python\Python311\Lib\site-packages\django\shortcuts.py", line 86, in get_object_or_404
    return queryset.get(*args, **kwargs)
           ^^^^^^^^^^^^^^^^^^^^^^^^^^^^^
  File "C:\Users\97797\AppData\Local\Programs\Python\Python311\Lib\site-packages\django\db\models\query.py", line 635, in get
    clone = self._chain() if self.query.combinator else self.filter(*args, **kwargs)
                                                        ^^^^^^^^^^^^^^^^^^^^^^^^^^^^
  File "C:\Users\97797\AppData\Local\Programs\Python\Python311\Lib\site-packages\django\db\models\query.py", line 1476, in filter
    return self._filter_or_exclude(False, args, kwargs)
           ^^^^^^^^^^^^^^^^^^^^^^^^^^^^^^^^^^^^^^^^^^^^
  File "C:\Users\97797\AppData\Local\Programs\Python\Python311\Lib\site-packages\django\db\models\query.py", line 1494, in _filter_or_exclude
    clone._filter_or_exclude_inplace(negate, args, kwargs)
  File "C:\Users\97797\AppData\Local\Programs\Python\Python311\Lib\site-packages\django\db\models\query.py", line 1501, in _filter_or_exclude_inplace
    self._query.add_q(Q(*args, **kwargs))
  File "C:\Users\97797\AppData\Local\Programs\Python\Python311\Lib\site-packages\django\db\models\sql\query.py", line 1609, in add_q
    clause, _ = self._add_q(q_object, self.used_aliases)
                ^^^^^^^^^^^^^^^^^^^^^^^^^^^^^^^^^^^^^^^^
  File "C:\Users\97797\AppData\Local\Programs\Python\Python311\Lib\site-packages\django\db\models\sql\query.py", line 1641, in _add_q
    child_clause, needed_inner = self.build_filter(
                                 ^^^^^^^^^^^^^^^^^^
  File "C:\Users\97797\AppData\Local\Programs\Python\Python311\Lib\site-packages\django\db\models\sql\query.py", line 1488, in build_filter
    arg, value = filter_expr
    ^^^^^^^^^^
  File "C:\Users\97797\AppData\Local\Programs\Python\Python311\Lib\site-packages\django\utils\functional.py", line 253, in inner
    return func(_wrapped, *args)
           ^^^^^^^^^^^^^^^^^^^^^
TypeError: 'CustomUser' object is not iterable
"POST /user/ HTTP/1.1" 500 126585
Internal Server Error: /user/
Traceback (most recent call last):
  File "C:\Users\97797\AppData\Local\Programs\Python\Python311\Lib\site-packages\django\core\handlers\exception.py", line 55, in inner
    response = get_response(request)
               ^^^^^^^^^^^^^^^^^^^^^
  File "C:\Users\97797\AppData\Local\Programs\Python\Python311\Lib\site-packages\django\core\handlers\base.py", line 197, in _get_response
    response = wrapped_callback(request, *callback_args, **callback_kwargs)
               ^^^^^^^^^^^^^^^^^^^^^^^^^^^^^^^^^^^^^^^^^^^^^^^^^^^^^^^^^^^^
  File "C:\Users\97797\AppData\Local\Programs\Python\Python311\Lib\site-packages\django\views\generic\base.py", line 104, in view
    return self.dispatch(request, *args, **kwargs)
           ^^^^^^^^^^^^^^^^^^^^^^^^^^^^^^^^^^^^^^^
  File "C:\Users\97797\AppData\Local\Programs\Python\Python311\Lib\site-packages\django\contrib\auth\mixins.py", line 73, in dispatch
    return super().dispatch(request, *args, **kwargs)
           ^^^^^^^^^^^^^^^^^^^^^^^^^^^^^^^^^^^^^^^^^^
  File "C:\Users\97797\AppData\Local\Programs\Python\Python311\Lib\site-packages\django\views\generic\base.py", line 143, in dispatch
    return handler(request, *args, **kwargs)
           ^^^^^^^^^^^^^^^^^^^^^^^^^^^^^^^^^
  File "C:\Users\97797\OneDrive\Desktop\Donation Manager Github\DonationManagementSystem\UserManagement\views.py", line 76, in post
    print(request.POST.profile_picture)
          ^^^^^^^^^^^^^^^^^^^^^^^^^^^^
AttributeError: 'QueryDict' object has no attribute 'profile_picture'
"POST /user/ HTTP/1.1" 500 83827
Internal Server Error: /user/
Traceback (most recent call last):
  File "C:\Users\97797\AppData\Local\Programs\Python\Python311\Lib\site-packages\django\utils\datastructures.py", line 84, in __getitem__
    list_ = super().__getitem__(key)
            ^^^^^^^^^^^^^^^^^^^^^^^^
KeyError: 'profile_pictures'

During handling of the above exception, another exception occurred:

Traceback (most recent call last):
  File "C:\Users\97797\AppData\Local\Programs\Python\Python311\Lib\site-packages\django\core\handlers\exception.py", line 55, in inner
    response = get_response(request)
               ^^^^^^^^^^^^^^^^^^^^^
  File "C:\Users\97797\AppData\Local\Programs\Python\Python311\Lib\site-packages\django\core\handlers\base.py", line 197, in _get_response
    response = wrapped_callback(request, *callback_args, **callback_kwargs)
               ^^^^^^^^^^^^^^^^^^^^^^^^^^^^^^^^^^^^^^^^^^^^^^^^^^^^^^^^^^^^
  File "C:\Users\97797\AppData\Local\Programs\Python\Python311\Lib\site-packages\django\views\generic\base.py", line 104, in view
    return self.dispatch(request, *args, **kwargs)
           ^^^^^^^^^^^^^^^^^^^^^^^^^^^^^^^^^^^^^^^
  File "C:\Users\97797\AppData\Local\Programs\Python\Python311\Lib\site-packages\django\contrib\auth\mixins.py", line 73, in dispatch
    return super().dispatch(request, *args, **kwargs)
           ^^^^^^^^^^^^^^^^^^^^^^^^^^^^^^^^^^^^^^^^^^
  File "C:\Users\97797\AppData\Local\Programs\Python\Python311\Lib\site-packages\django\views\generic\base.py", line 143, in dispatch
    return handler(request, *args, **kwargs)
           ^^^^^^^^^^^^^^^^^^^^^^^^^^^^^^^^^
  File "C:\Users\97797\OneDrive\Desktop\Donation Manager Github\DonationManagementSystem\UserManagement\views.py", line 77, in post
    user.profile_picture = request.FILES['profile_pictures']
                           ~~~~~~~~~~~~~^^^^^^^^^^^^^^^^^^^^
  File "C:\Users\97797\AppData\Local\Programs\Python\Python311\Lib\site-packages\django\utils\datastructures.py", line 86, in __getitem__
    raise MultiValueDictKeyError(key)
django.utils.datastructures.MultiValueDictKeyError: 'profile_pictures'
"POST /user/ HTTP/1.1" 500 92228
Internal Server Error: /user/
Traceback (most recent call last):
  File "C:\Users\97797\AppData\Local\Programs\Python\Python311\Lib\site-packages\django\db\models\fields\__init__.py", line 2123, in get_prep_value
    return int(value)
           ^^^^^^^^^^
TypeError: int() argument must be a string, a bytes-like object or a real number, not 'SimpleLazyObject'

The above exception was the direct cause of the following exception:

Traceback (most recent call last):
  File "C:\Users\97797\AppData\Local\Programs\Python\Python311\Lib\site-packages\django\core\handlers\exception.py", line 55, in inner
    response = get_response(request)
               ^^^^^^^^^^^^^^^^^^^^^
  File "C:\Users\97797\AppData\Local\Programs\Python\Python311\Lib\site-packages\django\core\handlers\base.py", line 197, in _get_response
    response = wrapped_callback(request, *callback_args, **callback_kwargs)
               ^^^^^^^^^^^^^^^^^^^^^^^^^^^^^^^^^^^^^^^^^^^^^^^^^^^^^^^^^^^^
  File "C:\Users\97797\AppData\Local\Programs\Python\Python311\Lib\site-packages\django\views\generic\base.py", line 104, in view
    return self.dispatch(request, *args, **kwargs)
           ^^^^^^^^^^^^^^^^^^^^^^^^^^^^^^^^^^^^^^^
  File "C:\Users\97797\AppData\Local\Programs\Python\Python311\Lib\site-packages\django\contrib\auth\mixins.py", line 73, in dispatch
    return super().dispatch(request, *args, **kwargs)
           ^^^^^^^^^^^^^^^^^^^^^^^^^^^^^^^^^^^^^^^^^^
  File "C:\Users\97797\AppData\Local\Programs\Python\Python311\Lib\site-packages\django\views\generic\base.py", line 143, in dispatch
    return handler(request, *args, **kwargs)
           ^^^^^^^^^^^^^^^^^^^^^^^^^^^^^^^^^
  File "C:\Users\97797\OneDrive\Desktop\Donation Manager Github\DonationManagementSystem\UserManagement\views.py", line 74, in post
    user.save()
  File "C:\Users\97797\OneDrive\Desktop\Donation Manager Github\DonationManagementSystem\UserManagement\models.py", line 20, in save
    return super().save(*args,**kwargs)
           ^^^^^^^^^^^^^^^^^^^^^^^^^^^^
  File "C:\Users\97797\AppData\Local\Programs\Python\Python311\Lib\site-packages\django\contrib\auth\base_user.py", line 62, in save
    super().save(*args, **kwargs)
  File "C:\Users\97797\AppData\Local\Programs\Python\Python311\Lib\site-packages\django\db\models\base.py", line 891, in save
    self.save_base(
  File "C:\Users\97797\AppData\Local\Programs\Python\Python311\Lib\site-packages\django\db\models\base.py", line 997, in save_base
    updated = self._save_table(
              ^^^^^^^^^^^^^^^^^
  File "C:\Users\97797\AppData\Local\Programs\Python\Python311\Lib\site-packages\django\db\models\base.py", line 1129, in _save_table
    updated = self._do_update(
              ^^^^^^^^^^^^^^^^
  File "C:\Users\97797\AppData\Local\Programs\Python\Python311\Lib\site-packages\django\db\models\base.py", line 1173, in _do_update
    filtered = base_qs.filter(pk=pk_val)
               ^^^^^^^^^^^^^^^^^^^^^^^^^
  File "C:\Users\97797\AppData\Local\Programs\Python\Python311\Lib\site-packages\django\db\models\query.py", line 1476, in filter
    return self._filter_or_exclude(False, args, kwargs)
           ^^^^^^^^^^^^^^^^^^^^^^^^^^^^^^^^^^^^^^^^^^^^
  File "C:\Users\97797\AppData\Local\Programs\Python\Python311\Lib\site-packages\django\db\models\query.py", line 1494, in _filter_or_exclude
    clone._filter_or_exclude_inplace(negate, args, kwargs)
  File "C:\Users\97797\AppData\Local\Programs\Python\Python311\Lib\site-packages\django\db\models\query.py", line 1501, in _filter_or_exclude_inplace
    self._query.add_q(Q(*args, **kwargs))
  File "C:\Users\97797\AppData\Local\Programs\Python\Python311\Lib\site-packages\django\db\models\sql\query.py", line 1609, in add_q
    clause, _ = self._add_q(q_object, self.used_aliases)
                ^^^^^^^^^^^^^^^^^^^^^^^^^^^^^^^^^^^^^^^^
  File "C:\Users\97797\AppData\Local\Programs\Python\Python311\Lib\site-packages\django\db\models\sql\query.py", line 1641, in _add_q
    child_clause, needed_inner = self.build_filter(
                                 ^^^^^^^^^^^^^^^^^^
  File "C:\Users\97797\AppData\Local\Programs\Python\Python311\Lib\site-packages\django\db\models\sql\query.py", line 1555, in build_filter
    condition = self.build_lookup(lookups, col, value)
                ^^^^^^^^^^^^^^^^^^^^^^^^^^^^^^^^^^^^^^
  File "C:\Users\97797\AppData\Local\Programs\Python\Python311\Lib\site-packages\django\db\models\sql\query.py", line 1385, in build_lookup
    lookup = lookup_class(lhs, rhs)
             ^^^^^^^^^^^^^^^^^^^^^^
  File "C:\Users\97797\AppData\Local\Programs\Python\Python311\Lib\site-packages\django\db\models\lookups.py", line 30, in __init__
    self.rhs = self.get_prep_lookup()
               ^^^^^^^^^^^^^^^^^^^^^^
  File "C:\Users\97797\AppData\Local\Programs\Python\Python311\Lib\site-packages\django\db\models\lookups.py", line 369, in get_prep_lookup
    return super().get_prep_lookup()
           ^^^^^^^^^^^^^^^^^^^^^^^^^
  File "C:\Users\97797\AppData\Local\Programs\Python\Python311\Lib\site-packages\django\db\models\lookups.py", line 88, in get_prep_lookup
    return self.lhs.output_field.get_prep_value(self.rhs)
           ^^^^^^^^^^^^^^^^^^^^^^^^^^^^^^^^^^^^^^^^^^^^^^
  File "C:\Users\97797\AppData\Local\Programs\Python\Python311\Lib\site-packages\django\db\models\fields\__init__.py", line 2125, in get_prep_value
    raise e.__class__(
TypeError: Field 'id' expected a number but got <SimpleLazyObject: <CustomUser: prabesh4>>.
"POST /user/ HTTP/1.1" 500 177300
Internal Server Error: /user/
Traceback (most recent call last):
  File "C:\Users\97797\AppData\Local\Programs\Python\Python311\Lib\site-packages\django\db\models\fields\__init__.py", line 2123, in get_prep_value
    return int(value)
           ^^^^^^^^^^
TypeError: int() argument must be a string, a bytes-like object or a real number, not 'SimpleLazyObject'

The above exception was the direct cause of the following exception:

Traceback (most recent call last):
  File "C:\Users\97797\AppData\Local\Programs\Python\Python311\Lib\site-packages\django\core\handlers\exception.py", line 55, in inner
    response = get_response(request)
               ^^^^^^^^^^^^^^^^^^^^^
  File "C:\Users\97797\AppData\Local\Programs\Python\Python311\Lib\site-packages\django\core\handlers\base.py", line 197, in _get_response
    response = wrapped_callback(request, *callback_args, **callback_kwargs)
               ^^^^^^^^^^^^^^^^^^^^^^^^^^^^^^^^^^^^^^^^^^^^^^^^^^^^^^^^^^^^
  File "C:\Users\97797\AppData\Local\Programs\Python\Python311\Lib\site-packages\django\views\generic\base.py", line 104, in view
    return self.dispatch(request, *args, **kwargs)
           ^^^^^^^^^^^^^^^^^^^^^^^^^^^^^^^^^^^^^^^
  File "C:\Users\97797\AppData\Local\Programs\Python\Python311\Lib\site-packages\django\contrib\auth\mixins.py", line 73, in dispatch
    return super().dispatch(request, *args, **kwargs)
           ^^^^^^^^^^^^^^^^^^^^^^^^^^^^^^^^^^^^^^^^^^
  File "C:\Users\97797\AppData\Local\Programs\Python\Python311\Lib\site-packages\django\views\generic\base.py", line 143, in dispatch
    return handler(request, *args, **kwargs)
           ^^^^^^^^^^^^^^^^^^^^^^^^^^^^^^^^^
  File "C:\Users\97797\OneDrive\Desktop\Donation Manager Github\DonationManagementSystem\UserManagement\views.py", line 74, in post
    user.save()
  File "C:\Users\97797\OneDrive\Desktop\Donation Manager Github\DonationManagementSystem\UserManagement\models.py", line 20, in save
    return super().save(*args,**kwargs)
           ^^^^^^^^^^^^^^^^^^^^^^^^^^^^
  File "C:\Users\97797\AppData\Local\Programs\Python\Python311\Lib\site-packages\django\contrib\auth\base_user.py", line 62, in save
    super().save(*args, **kwargs)
  File "C:\Users\97797\AppData\Local\Programs\Python\Python311\Lib\site-packages\django\db\models\base.py", line 891, in save
    self.save_base(
  File "C:\Users\97797\AppData\Local\Programs\Python\Python311\Lib\site-packages\django\db\models\base.py", line 997, in save_base
    updated = self._save_table(
              ^^^^^^^^^^^^^^^^^
  File "C:\Users\97797\AppData\Local\Programs\Python\Python311\Lib\site-packages\django\db\models\base.py", line 1129, in _save_table
    updated = self._do_update(
              ^^^^^^^^^^^^^^^^
  File "C:\Users\97797\AppData\Local\Programs\Python\Python311\Lib\site-packages\django\db\models\base.py", line 1173, in _do_update
    filtered = base_qs.filter(pk=pk_val)
               ^^^^^^^^^^^^^^^^^^^^^^^^^
  File "C:\Users\97797\AppData\Local\Programs\Python\Python311\Lib\site-packages\django\db\models\query.py", line 1476, in filter
    return self._filter_or_exclude(False, args, kwargs)
           ^^^^^^^^^^^^^^^^^^^^^^^^^^^^^^^^^^^^^^^^^^^^
  File "C:\Users\97797\AppData\Local\Programs\Python\Python311\Lib\site-packages\django\db\models\query.py", line 1494, in _filter_or_exclude
    clone._filter_or_exclude_inplace(negate, args, kwargs)
  File "C:\Users\97797\AppData\Local\Programs\Python\Python311\Lib\site-packages\django\db\models\query.py", line 1501, in _filter_or_exclude_inplace
    self._query.add_q(Q(*args, **kwargs))
  File "C:\Users\97797\AppData\Local\Programs\Python\Python311\Lib\site-packages\django\db\models\sql\query.py", line 1609, in add_q
    clause, _ = self._add_q(q_object, self.used_aliases)
                ^^^^^^^^^^^^^^^^^^^^^^^^^^^^^^^^^^^^^^^^
  File "C:\Users\97797\AppData\Local\Programs\Python\Python311\Lib\site-packages\django\db\models\sql\query.py", line 1641, in _add_q
    child_clause, needed_inner = self.build_filter(
                                 ^^^^^^^^^^^^^^^^^^
  File "C:\Users\97797\AppData\Local\Programs\Python\Python311\Lib\site-packages\django\db\models\sql\query.py", line 1555, in build_filter
    condition = self.build_lookup(lookups, col, value)
                ^^^^^^^^^^^^^^^^^^^^^^^^^^^^^^^^^^^^^^
  File "C:\Users\97797\AppData\Local\Programs\Python\Python311\Lib\site-packages\django\db\models\sql\query.py", line 1385, in build_lookup
    lookup = lookup_class(lhs, rhs)
             ^^^^^^^^^^^^^^^^^^^^^^
  File "C:\Users\97797\AppData\Local\Programs\Python\Python311\Lib\site-packages\django\db\models\lookups.py", line 30, in __init__
    self.rhs = self.get_prep_lookup()
               ^^^^^^^^^^^^^^^^^^^^^^
  File "C:\Users\97797\AppData\Local\Programs\Python\Python311\Lib\site-packages\django\db\models\lookups.py", line 369, in get_prep_lookup
    return super().get_prep_lookup()
           ^^^^^^^^^^^^^^^^^^^^^^^^^
  File "C:\Users\97797\AppData\Local\Programs\Python\Python311\Lib\site-packages\django\db\models\lookups.py", line 88, in get_prep_lookup
    return self.lhs.output_field.get_prep_value(self.rhs)
           ^^^^^^^^^^^^^^^^^^^^^^^^^^^^^^^^^^^^^^^^^^^^^^
  File "C:\Users\97797\AppData\Local\Programs\Python\Python311\Lib\site-packages\django\db\models\fields\__init__.py", line 2125, in get_prep_value
    raise e.__class__(
TypeError: Field 'id' expected a number but got <SimpleLazyObject: <CustomUser: prabesh4>>.
"POST /user/ HTTP/1.1" 500 177172
Internal Server Error: /user/
Traceback (most recent call last):
  File "C:\Users\97797\AppData\Local\Programs\Python\Python311\Lib\site-packages\django\db\models\fields\__init__.py", line 2123, in get_prep_value
    return int(value)
           ^^^^^^^^^^
TypeError: int() argument must be a string, a bytes-like object or a real number, not 'SimpleLazyObject'

The above exception was the direct cause of the following exception:

Traceback (most recent call last):
  File "C:\Users\97797\AppData\Local\Programs\Python\Python311\Lib\site-packages\django\core\handlers\exception.py", line 55, in inner
    response = get_response(request)
               ^^^^^^^^^^^^^^^^^^^^^
  File "C:\Users\97797\AppData\Local\Programs\Python\Python311\Lib\site-packages\django\core\handlers\base.py", line 197, in _get_response
    response = wrapped_callback(request, *callback_args, **callback_kwargs)
               ^^^^^^^^^^^^^^^^^^^^^^^^^^^^^^^^^^^^^^^^^^^^^^^^^^^^^^^^^^^^
  File "C:\Users\97797\AppData\Local\Programs\Python\Python311\Lib\site-packages\django\views\generic\base.py", line 104, in view
    return self.dispatch(request, *args, **kwargs)
           ^^^^^^^^^^^^^^^^^^^^^^^^^^^^^^^^^^^^^^^
  File "C:\Users\97797\AppData\Local\Programs\Python\Python311\Lib\site-packages\django\contrib\auth\mixins.py", line 73, in dispatch
    return super().dispatch(request, *args, **kwargs)
           ^^^^^^^^^^^^^^^^^^^^^^^^^^^^^^^^^^^^^^^^^^
  File "C:\Users\97797\AppData\Local\Programs\Python\Python311\Lib\site-packages\django\views\generic\base.py", line 143, in dispatch
    return handler(request, *args, **kwargs)
           ^^^^^^^^^^^^^^^^^^^^^^^^^^^^^^^^^
  File "C:\Users\97797\OneDrive\Desktop\Donation Manager Github\DonationManagementSystem\UserManagement\views.py", line 73, in post
    user = get_user_model().objects.get(pk=request.user.pk)
           ^^^^^^^^^^^^^^^^^^^^^^^^^^^^^^^^^^^^^^^^^^^^^
  File "C:\Users\97797\AppData\Local\Programs\Python\Python311\Lib\site-packages\django\db\models\manager.py", line 87, in manager_method
    return getattr(self.get_queryset(), name)(*args, **kwargs)
           ^^^^^^^^^^^^^^^^^^^^^^^^^^^^^^^^^^^^^^^^^^^^^^^^^^^
  File "C:\Users\97797\AppData\Local\Programs\Python\Python311\Lib\site-packages\django\db\models\query.py", line 635, in get
    clone = self._chain() if self.query.combinator else self.filter(*args, **kwargs)
                                                        ^^^^^^^^^^^^^^^^^^^^^^^^^^^^
  File "C:\Users\97797\AppData\Local\Programs\Python\Python311\Lib\site-packages\django\db\models\query.py", line 1476, in filter
    return self._filter_or_exclude(False, args, kwargs)
           ^^^^^^^^^^^^^^^^^^^^^^^^^^^^^^^^^^^^^^^^^^^^
  File "C:\Users\97797\AppData\Local\Programs\Python\Python311\Lib\site-packages\django\db\models\query.py", line 1494, in _filter_or_exclude
    clone._filter_or_exclude_inplace(negate, args, kwargs)
  File "C:\Users\97797\AppData\Local\Programs\Python\Python311\Lib\site-packages\django\db\models\query.py", line 1501, in _filter_or_exclude_inplace
    self._query.add_q(Q(*args, **kwargs))
  File "C:\Users\97797\AppData\Local\Programs\Python\Python311\Lib\site-packages\django\db\models\sql\query.py", line 1609, in add_q
    clause, _ = self._add_q(q_object, self.used_aliases)
                ^^^^^^^^^^^^^^^^^^^^^^^^^^^^^^^^^^^^^^^^
  File "C:\Users\97797\AppData\Local\Programs\Python\Python311\Lib\site-packages\django\db\models\sql\query.py", line 1641, in _add_q
    child_clause, needed_inner = self.build_filter(
                                 ^^^^^^^^^^^^^^^^^^
  File "C:\Users\97797\AppData\Local\Programs\Python\Python311\Lib\site-packages\django\db\models\sql\query.py", line 1555, in build_filter
    condition = self.build_lookup(lookups, col, value)
                ^^^^^^^^^^^^^^^^^^^^^^^^^^^^^^^^^^^^^^
  File "C:\Users\97797\AppData\Local\Programs\Python\Python311\Lib\site-packages\django\db\models\sql\query.py", line 1385, in build_lookup
    lookup = lookup_class(lhs, rhs)
             ^^^^^^^^^^^^^^^^^^^^^^
  File "C:\Users\97797\AppData\Local\Programs\Python\Python311\Lib\site-packages\django\db\models\lookups.py", line 30, in __init__
    self.rhs = self.get_prep_lookup()
               ^^^^^^^^^^^^^^^^^^^^^^
  File "C:\Users\97797\AppData\Local\Programs\Python\Python311\Lib\site-packages\django\db\models\lookups.py", line 369, in get_prep_lookup
    return super().get_prep_lookup()
           ^^^^^^^^^^^^^^^^^^^^^^^^^
  File "C:\Users\97797\AppData\Local\Programs\Python\Python311\Lib\site-packages\django\db\models\lookups.py", line 88, in get_prep_lookup
    return self.lhs.output_field.get_prep_value(self.rhs)
           ^^^^^^^^^^^^^^^^^^^^^^^^^^^^^^^^^^^^^^^^^^^^^^
  File "C:\Users\97797\AppData\Local\Programs\Python\Python311\Lib\site-packages\django\db\models\fields\__init__.py", line 2125, in get_prep_value
    raise e.__class__(
TypeError: Field 'id' expected a number but got <SimpleLazyObject: <CustomUser: prabesh4>>.
"POST /user/ HTTP/1.1" 500 152578
Internal Server Error: /user/
Traceback (most recent call last):
  File "C:\Users\97797\AppData\Local\Programs\Python\Python311\Lib\site-packages\django\db\models\fields\__init__.py", line 2123, in get_prep_value
    return int(value)
           ^^^^^^^^^^
TypeError: int() argument must be a string, a bytes-like object or a real number, not 'SimpleLazyObject'

The above exception was the direct cause of the following exception:

Traceback (most recent call last):
  File "C:\Users\97797\AppData\Local\Programs\Python\Python311\Lib\site-packages\django\core\handlers\exception.py", line 55, in inner
    response = get_response(request)
               ^^^^^^^^^^^^^^^^^^^^^
  File "C:\Users\97797\AppData\Local\Programs\Python\Python311\Lib\site-packages\django\core\handlers\base.py", line 197, in _get_response
    response = wrapped_callback(request, *callback_args, **callback_kwargs)
               ^^^^^^^^^^^^^^^^^^^^^^^^^^^^^^^^^^^^^^^^^^^^^^^^^^^^^^^^^^^^
  File "C:\Users\97797\AppData\Local\Programs\Python\Python311\Lib\site-packages\django\views\generic\base.py", line 104, in view
    return self.dispatch(request, *args, **kwargs)
           ^^^^^^^^^^^^^^^^^^^^^^^^^^^^^^^^^^^^^^^
  File "C:\Users\97797\AppData\Local\Programs\Python\Python311\Lib\site-packages\django\contrib\auth\mixins.py", line 73, in dispatch
    return super().dispatch(request, *args, **kwargs)
           ^^^^^^^^^^^^^^^^^^^^^^^^^^^^^^^^^^^^^^^^^^
  File "C:\Users\97797\AppData\Local\Programs\Python\Python311\Lib\site-packages\django\views\generic\base.py", line 143, in dispatch
    return handler(request, *args, **kwargs)
           ^^^^^^^^^^^^^^^^^^^^^^^^^^^^^^^^^
  File "C:\Users\97797\OneDrive\Desktop\Donation Manager Github\DonationManagementSystem\UserManagement\views.py", line 73, in post
    user = get_user_model().objects.get(pk=request.user.pk)
           ^^^^^^^^^^^^^^^^^^^^^^^^^^^^^^^^^^^^^^^^^^^^^
  File "C:\Users\97797\AppData\Local\Programs\Python\Python311\Lib\site-packages\django\db\models\manager.py", line 87, in manager_method
    return getattr(self.get_queryset(), name)(*args, **kwargs)
           ^^^^^^^^^^^^^^^^^^^^^^^^^^^^^^^^^^^^^^^^^^^^^^^^^^^
  File "C:\Users\97797\AppData\Local\Programs\Python\Python311\Lib\site-packages\django\db\models\query.py", line 635, in get
    clone = self._chain() if self.query.combinator else self.filter(*args, **kwargs)
                                                        ^^^^^^^^^^^^^^^^^^^^^^^^^^^^
  File "C:\Users\97797\AppData\Local\Programs\Python\Python311\Lib\site-packages\django\db\models\query.py", line 1476, in filter
    return self._filter_or_exclude(False, args, kwargs)
           ^^^^^^^^^^^^^^^^^^^^^^^^^^^^^^^^^^^^^^^^^^^^
  File "C:\Users\97797\AppData\Local\Programs\Python\Python311\Lib\site-packages\django\db\models\query.py", line 1494, in _filter_or_exclude
    clone._filter_or_exclude_inplace(negate, args, kwargs)
  File "C:\Users\97797\AppData\Local\Programs\Python\Python311\Lib\site-packages\django\db\models\query.py", line 1501, in _filter_or_exclude_inplace
    self._query.add_q(Q(*args, **kwargs))
  File "C:\Users\97797\AppData\Local\Programs\Python\Python311\Lib\site-packages\django\db\models\sql\query.py", line 1609, in add_q
    clause, _ = self._add_q(q_object, self.used_aliases)
                ^^^^^^^^^^^^^^^^^^^^^^^^^^^^^^^^^^^^^^^^
  File "C:\Users\97797\AppData\Local\Programs\Python\Python311\Lib\site-packages\django\db\models\sql\query.py", line 1641, in _add_q
    child_clause, needed_inner = self.build_filter(
                                 ^^^^^^^^^^^^^^^^^^
  File "C:\Users\97797\AppData\Local\Programs\Python\Python311\Lib\site-packages\django\db\models\sql\query.py", line 1555, in build_filter
    condition = self.build_lookup(lookups, col, value)
                ^^^^^^^^^^^^^^^^^^^^^^^^^^^^^^^^^^^^^^
  File "C:\Users\97797\AppData\Local\Programs\Python\Python311\Lib\site-packages\django\db\models\sql\query.py", line 1385, in build_lookup
    lookup = lookup_class(lhs, rhs)
             ^^^^^^^^^^^^^^^^^^^^^^
  File "C:\Users\97797\AppData\Local\Programs\Python\Python311\Lib\site-packages\django\db\models\lookups.py", line 30, in __init__
    self.rhs = self.get_prep_lookup()
               ^^^^^^^^^^^^^^^^^^^^^^
  File "C:\Users\97797\AppData\Local\Programs\Python\Python311\Lib\site-packages\django\db\models\lookups.py", line 369, in get_prep_lookup
    return super().get_prep_lookup()
           ^^^^^^^^^^^^^^^^^^^^^^^^^
  File "C:\Users\97797\AppData\Local\Programs\Python\Python311\Lib\site-packages\django\db\models\lookups.py", line 88, in get_prep_lookup
    return self.lhs.output_field.get_prep_value(self.rhs)
           ^^^^^^^^^^^^^^^^^^^^^^^^^^^^^^^^^^^^^^^^^^^^^^
  File "C:\Users\97797\AppData\Local\Programs\Python\Python311\Lib\site-packages\django\db\models\fields\__init__.py", line 2125, in get_prep_value
    raise e.__class__(
TypeError: Field 'id' expected a number but got <SimpleLazyObject: <CustomUser: prabesh4>>.
"POST /user/ HTTP/1.1" 500 152579
Internal Server Error: /user/
Traceback (most recent call last):
  File "C:\Users\97797\AppData\Local\Programs\Python\Python311\Lib\site-packages\django\core\handlers\exception.py", line 55, in inner
    response = get_response(request)
               ^^^^^^^^^^^^^^^^^^^^^
  File "C:\Users\97797\AppData\Local\Programs\Python\Python311\Lib\site-packages\django\core\handlers\base.py", line 197, in _get_response
    response = wrapped_callback(request, *callback_args, **callback_kwargs)
               ^^^^^^^^^^^^^^^^^^^^^^^^^^^^^^^^^^^^^^^^^^^^^^^^^^^^^^^^^^^^
  File "C:\Users\97797\AppData\Local\Programs\Python\Python311\Lib\site-packages\django\views\generic\base.py", line 104, in view
    return self.dispatch(request, *args, **kwargs)
           ^^^^^^^^^^^^^^^^^^^^^^^^^^^^^^^^^^^^^^^
  File "C:\Users\97797\AppData\Local\Programs\Python\Python311\Lib\site-packages\django\contrib\auth\mixins.py", line 73, in dispatch
    return super().dispatch(request, *args, **kwargs)
           ^^^^^^^^^^^^^^^^^^^^^^^^^^^^^^^^^^^^^^^^^^
  File "C:\Users\97797\AppData\Local\Programs\Python\Python311\Lib\site-packages\django\views\generic\base.py", line 143, in dispatch
    return handler(request, *args, **kwargs)
           ^^^^^^^^^^^^^^^^^^^^^^^^^^^^^^^^^
  File "C:\Users\97797\OneDrive\Desktop\Donation Manager Github\DonationManagementSystem\UserManagement\views.py", line 77, in post
    user = CustomUser().objects.get(pk=user.pk)
           ^^^^^^^^^^^^^^^^^^^^
  File "C:\Users\97797\AppData\Local\Programs\Python\Python311\Lib\site-packages\django\db\models\manager.py", line 186, in __get__
    raise AttributeError(
AttributeError: Manager isn't accessible via CustomUser instances
"POST /user/ HTTP/1.1" 500 88060
Internal Server Error: /user/
Traceback (most recent call last):
  File "C:\Users\97797\AppData\Local\Programs\Python\Python311\Lib\site-packages\django\core\handlers\exception.py", line 55, in inner
    response = get_response(request)
               ^^^^^^^^^^^^^^^^^^^^^
  File "C:\Users\97797\AppData\Local\Programs\Python\Python311\Lib\site-packages\django\core\handlers\base.py", line 197, in _get_response
    response = wrapped_callback(request, *callback_args, **callback_kwargs)
               ^^^^^^^^^^^^^^^^^^^^^^^^^^^^^^^^^^^^^^^^^^^^^^^^^^^^^^^^^^^^
  File "C:\Users\97797\AppData\Local\Programs\Python\Python311\Lib\site-packages\django\views\generic\base.py", line 104, in view
    return self.dispatch(request, *args, **kwargs)
           ^^^^^^^^^^^^^^^^^^^^^^^^^^^^^^^^^^^^^^^
  File "C:\Users\97797\AppData\Local\Programs\Python\Python311\Lib\site-packages\django\contrib\auth\mixins.py", line 73, in dispatch
    return super().dispatch(request, *args, **kwargs)
           ^^^^^^^^^^^^^^^^^^^^^^^^^^^^^^^^^^^^^^^^^^
  File "C:\Users\97797\AppData\Local\Programs\Python\Python311\Lib\site-packages\django\views\generic\base.py", line 143, in dispatch
    return handler(request, *args, **kwargs)
           ^^^^^^^^^^^^^^^^^^^^^^^^^^^^^^^^^
  File "C:\Users\97797\AppData\Local\Programs\Python\Python311\Lib\site-packages\django\views\generic\base.py", line 226, in get
    context = self.get_context_data(**kwargs)
              ^^^^^^^^^^^^^^^^^^^^^^^^^^^^^^^
  File "C:\Users\97797\OneDrive\Desktop\Donation Manager Github\DonationManagementSystem\UserManagement\views.py", line 69, in get_context_data
    context['profile_picture'] = self.request.user['profile_picture']
                                 ~~~~~~~~~~~~~~~~~^^^^^^^^^^^^^^^^^^^
  File "C:\Users\97797\AppData\Local\Programs\Python\Python311\Lib\site-packages\django\utils\functional.py", line 253, in inner
    return func(_wrapped, *args)
           ^^^^^^^^^^^^^^^^^^^^^
TypeError: 'CustomUser' object is not subscriptable
"GET /user/ HTTP/1.1" 500 91862
Internal Server Error: /user/
Traceback (most recent call last):
  File "C:\Users\97797\AppData\Local\Programs\Python\Python311\Lib\site-packages\django\core\handlers\exception.py", line 55, in inner
    response = get_response(request)
               ^^^^^^^^^^^^^^^^^^^^^
  File "C:\Users\97797\AppData\Local\Programs\Python\Python311\Lib\site-packages\django\core\handlers\base.py", line 197, in _get_response
    response = wrapped_callback(request, *callback_args, **callback_kwargs)
               ^^^^^^^^^^^^^^^^^^^^^^^^^^^^^^^^^^^^^^^^^^^^^^^^^^^^^^^^^^^^
  File "C:\Users\97797\AppData\Local\Programs\Python\Python311\Lib\site-packages\django\views\generic\base.py", line 104, in view
    return self.dispatch(request, *args, **kwargs)
           ^^^^^^^^^^^^^^^^^^^^^^^^^^^^^^^^^^^^^^^
  File "C:\Users\97797\AppData\Local\Programs\Python\Python311\Lib\site-packages\django\contrib\auth\mixins.py", line 73, in dispatch
    return super().dispatch(request, *args, **kwargs)
           ^^^^^^^^^^^^^^^^^^^^^^^^^^^^^^^^^^^^^^^^^^
  File "C:\Users\97797\AppData\Local\Programs\Python\Python311\Lib\site-packages\django\views\generic\base.py", line 143, in dispatch
    return handler(request, *args, **kwargs)
           ^^^^^^^^^^^^^^^^^^^^^^^^^^^^^^^^^
  File "C:\Users\97797\AppData\Local\Programs\Python\Python311\Lib\site-packages\django\views\generic\base.py", line 226, in get
    context = self.get_context_data(**kwargs)
              ^^^^^^^^^^^^^^^^^^^^^^^^^^^^^^^
  File "C:\Users\97797\OneDrive\Desktop\Donation Manager Github\DonationManagementSystem\UserManagement\views.py", line 69, in get_context_data
    context['profile_picture'] = self.request.user.get('profile_picture')
                                 ^^^^^^^^^^^^^^^^^^^^^
  File "C:\Users\97797\AppData\Local\Programs\Python\Python311\Lib\site-packages\django\utils\functional.py", line 253, in inner
    return func(_wrapped, *args)
           ^^^^^^^^^^^^^^^^^^^^^
AttributeError: 'CustomUser' object has no attribute 'get'
"GET /user/ HTTP/1.1" 500 91906
Internal Server Error: /user/
Traceback (most recent call last):
  File "C:\Users\97797\AppData\Local\Programs\Python\Python311\Lib\site-packages\django\template\base.py", line 883, in _resolve_lookup
    current = current[bit]
              ~~~~~~~^^^^^
TypeError: 'ImageFieldFile' object is not subscriptable

During handling of the above exception, another exception occurred:

Traceback (most recent call last):
  File "C:\Users\97797\AppData\Local\Programs\Python\Python311\Lib\site-packages\django\core\handlers\exception.py", line 55, in inner
    response = get_response(request)
               ^^^^^^^^^^^^^^^^^^^^^
  File "C:\Users\97797\AppData\Local\Programs\Python\Python311\Lib\site-packages\django\core\handlers\base.py", line 220, in _get_response
    response = response.render()
               ^^^^^^^^^^^^^^^^^
  File "C:\Users\97797\AppData\Local\Programs\Python\Python311\Lib\site-packages\django\template\response.py", line 114, in render
    self.content = self.rendered_content
                   ^^^^^^^^^^^^^^^^^^^^^
  File "C:\Users\97797\AppData\Local\Programs\Python\Python311\Lib\site-packages\django\template\response.py", line 92, in rendered_content
    return template.render(context, self._request)
           ^^^^^^^^^^^^^^^^^^^^^^^^^^^^^^^^^^^^^^^
  File "C:\Users\97797\AppData\Local\Programs\Python\Python311\Lib\site-packages\django\template\backends\django.py", line 107, in render
    return self.template.render(context)
           ^^^^^^^^^^^^^^^^^^^^^^^^^^^^^
  File "C:\Users\97797\AppData\Local\Programs\Python\Python311\Lib\site-packages\django\template\base.py", line 171, in render
    return self._render(context)
           ^^^^^^^^^^^^^^^^^^^^^
  File "C:\Users\97797\AppData\Local\Programs\Python\Python311\Lib\site-packages\django\template\base.py", line 163, in _render
    return self.nodelist.render(context)
           ^^^^^^^^^^^^^^^^^^^^^^^^^^^^^
  File "C:\Users\97797\AppData\Local\Programs\Python\Python311\Lib\site-packages\django\template\base.py", line 1008, in render
    return SafeString("".join([node.render_annotated(context) for node in self]))
                              ^^^^^^^^^^^^^^^^^^^^^^^^^^^^^^^^^^^^^^^^^^^^^^^^^
  File "C:\Users\97797\AppData\Local\Programs\Python\Python311\Lib\site-packages\django\template\base.py", line 1008, in <listcomp>
    return SafeString("".join([node.render_annotated(context) for node in self]))
                               ^^^^^^^^^^^^^^^^^^^^^^^^^^^^^^
  File "C:\Users\97797\AppData\Local\Programs\Python\Python311\Lib\site-packages\django\template\base.py", line 969, in render_annotated
    return self.render(context)
           ^^^^^^^^^^^^^^^^^^^^
  File "C:\Users\97797\AppData\Local\Programs\Python\Python311\Lib\site-packages\django\template\loader_tags.py", line 159, in render
    return compiled_parent._render(context)
           ^^^^^^^^^^^^^^^^^^^^^^^^^^^^^^^^
  File "C:\Users\97797\AppData\Local\Programs\Python\Python311\Lib\site-packages\django\template\base.py", line 163, in _render
    return self.nodelist.render(context)
           ^^^^^^^^^^^^^^^^^^^^^^^^^^^^^
  File "C:\Users\97797\AppData\Local\Programs\Python\Python311\Lib\site-packages\django\template\base.py", line 1008, in render
    return SafeString("".join([node.render_annotated(context) for node in self]))
                              ^^^^^^^^^^^^^^^^^^^^^^^^^^^^^^^^^^^^^^^^^^^^^^^^^
  File "C:\Users\97797\AppData\Local\Programs\Python\Python311\Lib\site-packages\django\template\base.py", line 1008, in <listcomp>
    return SafeString("".join([node.render_annotated(context) for node in self]))
                               ^^^^^^^^^^^^^^^^^^^^^^^^^^^^^^
  File "C:\Users\97797\AppData\Local\Programs\Python\Python311\Lib\site-packages\django\template\base.py", line 969, in render_annotated
    return self.render(context)
           ^^^^^^^^^^^^^^^^^^^^
  File "C:\Users\97797\AppData\Local\Programs\Python\Python311\Lib\site-packages\django\template\loader_tags.py", line 65, in render
    result = block.nodelist.render(context)
             ^^^^^^^^^^^^^^^^^^^^^^^^^^^^^^
  File "C:\Users\97797\AppData\Local\Programs\Python\Python311\Lib\site-packages\django\template\base.py", line 1008, in render
    return SafeString("".join([node.render_annotated(context) for node in self]))
                              ^^^^^^^^^^^^^^^^^^^^^^^^^^^^^^^^^^^^^^^^^^^^^^^^^
  File "C:\Users\97797\AppData\Local\Programs\Python\Python311\Lib\site-packages\django\template\base.py", line 1008, in <listcomp>
    return SafeString("".join([node.render_annotated(context) for node in self]))
                               ^^^^^^^^^^^^^^^^^^^^^^^^^^^^^^
  File "C:\Users\97797\AppData\Local\Programs\Python\Python311\Lib\site-packages\django\template\base.py", line 969, in render_annotated
    return self.render(context)
           ^^^^^^^^^^^^^^^^^^^^
  File "C:\Users\97797\AppData\Local\Programs\Python\Python311\Lib\site-packages\django\template\base.py", line 1067, in render
    output = self.filter_expression.resolve(context)
             ^^^^^^^^^^^^^^^^^^^^^^^^^^^^^^^^^^^^^^^
  File "C:\Users\97797\AppData\Local\Programs\Python\Python311\Lib\site-packages\django\template\base.py", line 718, in resolve
    obj = self.var.resolve(context)
          ^^^^^^^^^^^^^^^^^^^^^^^^^
  File "C:\Users\97797\AppData\Local\Programs\Python\Python311\Lib\site-packages\django\template\base.py", line 850, in resolve
    value = self._resolve_lookup(context)
            ^^^^^^^^^^^^^^^^^^^^^^^^^^^^^
  File "C:\Users\97797\AppData\Local\Programs\Python\Python311\Lib\site-packages\django\template\base.py", line 893, in _resolve_lookup
    current = getattr(current, bit)
              ^^^^^^^^^^^^^^^^^^^^^
  File "C:\Users\97797\AppData\Local\Programs\Python\Python311\Lib\site-packages\django\db\models\fields\files.py", line 69, in url
    self._require_file()
  File "C:\Users\97797\AppData\Local\Programs\Python\Python311\Lib\site-packages\django\db\models\fields\files.py", line 44, in _require_file
    raise ValueError(
ValueError: The 'profile_picture' attribute has no file associated with it.
"GET /user/ HTTP/1.1" 500 187957
Internal Server Error: /user/
Traceback (most recent call last):
  File "C:\Users\97797\AppData\Local\Programs\Python\Python311\Lib\site-packages\django\template\base.py", line 883, in _resolve_lookup
    current = current[bit]
              ~~~~~~~^^^^^
TypeError: 'ImageFieldFile' object is not subscriptable

During handling of the above exception, another exception occurred:

Traceback (most recent call last):
  File "C:\Users\97797\AppData\Local\Programs\Python\Python311\Lib\site-packages\django\core\handlers\exception.py", line 55, in inner
    response = get_response(request)
               ^^^^^^^^^^^^^^^^^^^^^
  File "C:\Users\97797\AppData\Local\Programs\Python\Python311\Lib\site-packages\django\core\handlers\base.py", line 220, in _get_response
    response = response.render()
               ^^^^^^^^^^^^^^^^^
  File "C:\Users\97797\AppData\Local\Programs\Python\Python311\Lib\site-packages\django\template\response.py", line 114, in render
    self.content = self.rendered_content
                   ^^^^^^^^^^^^^^^^^^^^^
  File "C:\Users\97797\AppData\Local\Programs\Python\Python311\Lib\site-packages\django\template\response.py", line 92, in rendered_content
    return template.render(context, self._request)
           ^^^^^^^^^^^^^^^^^^^^^^^^^^^^^^^^^^^^^^^
  File "C:\Users\97797\AppData\Local\Programs\Python\Python311\Lib\site-packages\django\template\backends\django.py", line 107, in render
    return self.template.render(context)
           ^^^^^^^^^^^^^^^^^^^^^^^^^^^^^
  File "C:\Users\97797\AppData\Local\Programs\Python\Python311\Lib\site-packages\django\template\base.py", line 171, in render
    return self._render(context)
           ^^^^^^^^^^^^^^^^^^^^^
  File "C:\Users\97797\AppData\Local\Programs\Python\Python311\Lib\site-packages\django\template\base.py", line 163, in _render
    return self.nodelist.render(context)
           ^^^^^^^^^^^^^^^^^^^^^^^^^^^^^
  File "C:\Users\97797\AppData\Local\Programs\Python\Python311\Lib\site-packages\django\template\base.py", line 1008, in render
    return SafeString("".join([node.render_annotated(context) for node in self]))
                              ^^^^^^^^^^^^^^^^^^^^^^^^^^^^^^^^^^^^^^^^^^^^^^^^^
  File "C:\Users\97797\AppData\Local\Programs\Python\Python311\Lib\site-packages\django\template\base.py", line 1008, in <listcomp>
    return SafeString("".join([node.render_annotated(context) for node in self]))
                               ^^^^^^^^^^^^^^^^^^^^^^^^^^^^^^
  File "C:\Users\97797\AppData\Local\Programs\Python\Python311\Lib\site-packages\django\template\base.py", line 969, in render_annotated
    return self.render(context)
           ^^^^^^^^^^^^^^^^^^^^
  File "C:\Users\97797\AppData\Local\Programs\Python\Python311\Lib\site-packages\django\template\loader_tags.py", line 159, in render
    return compiled_parent._render(context)
           ^^^^^^^^^^^^^^^^^^^^^^^^^^^^^^^^
  File "C:\Users\97797\AppData\Local\Programs\Python\Python311\Lib\site-packages\django\template\base.py", line 163, in _render
    return self.nodelist.render(context)
           ^^^^^^^^^^^^^^^^^^^^^^^^^^^^^
  File "C:\Users\97797\AppData\Local\Programs\Python\Python311\Lib\site-packages\django\template\base.py", line 1008, in render
    return SafeString("".join([node.render_annotated(context) for node in self]))
                              ^^^^^^^^^^^^^^^^^^^^^^^^^^^^^^^^^^^^^^^^^^^^^^^^^
  File "C:\Users\97797\AppData\Local\Programs\Python\Python311\Lib\site-packages\django\template\base.py", line 1008, in <listcomp>
    return SafeString("".join([node.render_annotated(context) for node in self]))
                               ^^^^^^^^^^^^^^^^^^^^^^^^^^^^^^
  File "C:\Users\97797\AppData\Local\Programs\Python\Python311\Lib\site-packages\django\template\base.py", line 969, in render_annotated
    return self.render(context)
           ^^^^^^^^^^^^^^^^^^^^
  File "C:\Users\97797\AppData\Local\Programs\Python\Python311\Lib\site-packages\django\template\loader_tags.py", line 65, in render
    result = block.nodelist.render(context)
             ^^^^^^^^^^^^^^^^^^^^^^^^^^^^^^
  File "C:\Users\97797\AppData\Local\Programs\Python\Python311\Lib\site-packages\django\template\base.py", line 1008, in render
    return SafeString("".join([node.render_annotated(context) for node in self]))
                              ^^^^^^^^^^^^^^^^^^^^^^^^^^^^^^^^^^^^^^^^^^^^^^^^^
  File "C:\Users\97797\AppData\Local\Programs\Python\Python311\Lib\site-packages\django\template\base.py", line 1008, in <listcomp>
    return SafeString("".join([node.render_annotated(context) for node in self]))
                               ^^^^^^^^^^^^^^^^^^^^^^^^^^^^^^
  File "C:\Users\97797\AppData\Local\Programs\Python\Python311\Lib\site-packages\django\template\base.py", line 969, in render_annotated
    return self.render(context)
           ^^^^^^^^^^^^^^^^^^^^
  File "C:\Users\97797\AppData\Local\Programs\Python\Python311\Lib\site-packages\django\template\base.py", line 1067, in render
    output = self.filter_expression.resolve(context)
             ^^^^^^^^^^^^^^^^^^^^^^^^^^^^^^^^^^^^^^^
  File "C:\Users\97797\AppData\Local\Programs\Python\Python311\Lib\site-packages\django\template\base.py", line 718, in resolve
    obj = self.var.resolve(context)
          ^^^^^^^^^^^^^^^^^^^^^^^^^
  File "C:\Users\97797\AppData\Local\Programs\Python\Python311\Lib\site-packages\django\template\base.py", line 850, in resolve
    value = self._resolve_lookup(context)
            ^^^^^^^^^^^^^^^^^^^^^^^^^^^^^
  File "C:\Users\97797\AppData\Local\Programs\Python\Python311\Lib\site-packages\django\template\base.py", line 893, in _resolve_lookup
    current = getattr(current, bit)
              ^^^^^^^^^^^^^^^^^^^^^
  File "C:\Users\97797\AppData\Local\Programs\Python\Python311\Lib\site-packages\django\db\models\fields\files.py", line 69, in url
    self._require_file()
  File "C:\Users\97797\AppData\Local\Programs\Python\Python311\Lib\site-packages\django\db\models\fields\files.py", line 44, in _require_file
    raise ValueError(
ValueError: The 'profile_picture' attribute has no file associated with it.
"GET /user/ HTTP/1.1" 500 187957
Internal Server Error: /user/
Traceback (most recent call last):
  File "C:\Users\97797\AppData\Local\Programs\Python\Python311\Lib\site-packages\django\template\base.py", line 883, in _resolve_lookup
    current = current[bit]
              ~~~~~~~^^^^^
TypeError: 'ImageFieldFile' object is not subscriptable

During handling of the above exception, another exception occurred:

Traceback (most recent call last):
  File "C:\Users\97797\AppData\Local\Programs\Python\Python311\Lib\site-packages\django\core\handlers\exception.py", line 55, in inner
    response = get_response(request)
               ^^^^^^^^^^^^^^^^^^^^^
  File "C:\Users\97797\AppData\Local\Programs\Python\Python311\Lib\site-packages\django\core\handlers\base.py", line 220, in _get_response
    response = response.render()
               ^^^^^^^^^^^^^^^^^
  File "C:\Users\97797\AppData\Local\Programs\Python\Python311\Lib\site-packages\django\template\response.py", line 114, in render
    self.content = self.rendered_content
                   ^^^^^^^^^^^^^^^^^^^^^
  File "C:\Users\97797\AppData\Local\Programs\Python\Python311\Lib\site-packages\django\template\response.py", line 92, in rendered_content
    return template.render(context, self._request)
           ^^^^^^^^^^^^^^^^^^^^^^^^^^^^^^^^^^^^^^^
  File "C:\Users\97797\AppData\Local\Programs\Python\Python311\Lib\site-packages\django\template\backends\django.py", line 107, in render
    return self.template.render(context)
           ^^^^^^^^^^^^^^^^^^^^^^^^^^^^^
  File "C:\Users\97797\AppData\Local\Programs\Python\Python311\Lib\site-packages\django\template\base.py", line 171, in render
    return self._render(context)
           ^^^^^^^^^^^^^^^^^^^^^
  File "C:\Users\97797\AppData\Local\Programs\Python\Python311\Lib\site-packages\django\template\base.py", line 163, in _render
    return self.nodelist.render(context)
           ^^^^^^^^^^^^^^^^^^^^^^^^^^^^^
  File "C:\Users\97797\AppData\Local\Programs\Python\Python311\Lib\site-packages\django\template\base.py", line 1008, in render
    return SafeString("".join([node.render_annotated(context) for node in self]))
                              ^^^^^^^^^^^^^^^^^^^^^^^^^^^^^^^^^^^^^^^^^^^^^^^^^
  File "C:\Users\97797\AppData\Local\Programs\Python\Python311\Lib\site-packages\django\template\base.py", line 1008, in <listcomp>
    return SafeString("".join([node.render_annotated(context) for node in self]))
                               ^^^^^^^^^^^^^^^^^^^^^^^^^^^^^^
  File "C:\Users\97797\AppData\Local\Programs\Python\Python311\Lib\site-packages\django\template\base.py", line 969, in render_annotated
    return self.render(context)
           ^^^^^^^^^^^^^^^^^^^^
  File "C:\Users\97797\AppData\Local\Programs\Python\Python311\Lib\site-packages\django\template\loader_tags.py", line 159, in render
    return compiled_parent._render(context)
           ^^^^^^^^^^^^^^^^^^^^^^^^^^^^^^^^
  File "C:\Users\97797\AppData\Local\Programs\Python\Python311\Lib\site-packages\django\template\base.py", line 163, in _render
    return self.nodelist.render(context)
           ^^^^^^^^^^^^^^^^^^^^^^^^^^^^^
  File "C:\Users\97797\AppData\Local\Programs\Python\Python311\Lib\site-packages\django\template\base.py", line 1008, in render
    return SafeString("".join([node.render_annotated(context) for node in self]))
                              ^^^^^^^^^^^^^^^^^^^^^^^^^^^^^^^^^^^^^^^^^^^^^^^^^
  File "C:\Users\97797\AppData\Local\Programs\Python\Python311\Lib\site-packages\django\template\base.py", line 1008, in <listcomp>
    return SafeString("".join([node.render_annotated(context) for node in self]))
                               ^^^^^^^^^^^^^^^^^^^^^^^^^^^^^^
  File "C:\Users\97797\AppData\Local\Programs\Python\Python311\Lib\site-packages\django\template\base.py", line 969, in render_annotated
    return self.render(context)
           ^^^^^^^^^^^^^^^^^^^^
  File "C:\Users\97797\AppData\Local\Programs\Python\Python311\Lib\site-packages\django\template\loader_tags.py", line 65, in render
    result = block.nodelist.render(context)
             ^^^^^^^^^^^^^^^^^^^^^^^^^^^^^^
  File "C:\Users\97797\AppData\Local\Programs\Python\Python311\Lib\site-packages\django\template\base.py", line 1008, in render
    return SafeString("".join([node.render_annotated(context) for node in self]))
                              ^^^^^^^^^^^^^^^^^^^^^^^^^^^^^^^^^^^^^^^^^^^^^^^^^
  File "C:\Users\97797\AppData\Local\Programs\Python\Python311\Lib\site-packages\django\template\base.py", line 1008, in <listcomp>
    return SafeString("".join([node.render_annotated(context) for node in self]))
                               ^^^^^^^^^^^^^^^^^^^^^^^^^^^^^^
  File "C:\Users\97797\AppData\Local\Programs\Python\Python311\Lib\site-packages\django\template\base.py", line 969, in render_annotated
    return self.render(context)
           ^^^^^^^^^^^^^^^^^^^^
  File "C:\Users\97797\AppData\Local\Programs\Python\Python311\Lib\site-packages\django\template\base.py", line 1067, in render
    output = self.filter_expression.resolve(context)
             ^^^^^^^^^^^^^^^^^^^^^^^^^^^^^^^^^^^^^^^
  File "C:\Users\97797\AppData\Local\Programs\Python\Python311\Lib\site-packages\django\template\base.py", line 718, in resolve
    obj = self.var.resolve(context)
          ^^^^^^^^^^^^^^^^^^^^^^^^^
  File "C:\Users\97797\AppData\Local\Programs\Python\Python311\Lib\site-packages\django\template\base.py", line 850, in resolve
    value = self._resolve_lookup(context)
            ^^^^^^^^^^^^^^^^^^^^^^^^^^^^^
  File "C:\Users\97797\AppData\Local\Programs\Python\Python311\Lib\site-packages\django\template\base.py", line 893, in _resolve_lookup
    current = getattr(current, bit)
              ^^^^^^^^^^^^^^^^^^^^^
  File "C:\Users\97797\AppData\Local\Programs\Python\Python311\Lib\site-packages\django\db\models\fields\files.py", line 69, in url
    self._require_file()
  File "C:\Users\97797\AppData\Local\Programs\Python\Python311\Lib\site-packages\django\db\models\fields\files.py", line 44, in _require_file
    raise ValueError(
ValueError: The 'profile_picture' attribute has no file associated with it.
"GET /user/ HTTP/1.1" 500 187971
